<?xml version="1.0"?>
<robot name="moonpie_robot" xmlns:xacro="http://www.ros.org/wiki/xacro">

  <!-- Base Link -->
  <link name="base_link">
    <visual>
      <geometry>
        <box size="0.5 0.3 0.1"/>
      </geometry>
      <material name="blue">
        <color rgba="0 0 1 1"/>
      </material>
    </visual>
    <collision>
      <geometry>
        <box size="0.5 0.3 0.1"/>
      </geometry>
    </collision>
    <inertial>
      <mass value="5.0"/>
      <inertia ixx="0.1" ixy="0" ixz="0" iyy="0.1" iyz="0" izz="0.1"/>
    </inertial>
  </link>

  <!-- Wheels -->
  <link name="wheel_front_left">
    <visual>
      <geometry>
        <cylinder radius="0.05" length="0.04"/>
      </geometry>
      <material name="black">
        <color rgba="0 0 0 1"/>
      </material>
    </visual>
    <collision>
      <geometry>
        <cylinder radius="0.05" length="0.04"/>
      </geometry>
    </collision>
    <inertial>
      <mass value="0.1"/>
      <inertia ixx="0.001" ixy="0" ixz="0" iyy="0.001" iyz="0" izz="0.001"/>
    </inertial>
  </link>

  <link name="wheel_front_right">
    <visual>
      <geometry>
        <cylinder radius="0.05" length="0.04"/>
      </geometry>
      <material name="black">
        <color rgba="0 0 0 1"/>
      </material>
    </visual>
    <collision>
      <geometry>
        <cylinder radius="0.05" length="0.04"/>
      </geometry>
    </collision>
    <inertial>
      <mass value="0.1"/>
      <inertia ixx="0.001" ixy="0" ixz="0" iyy="0.001" iyz="0" izz="0.001"/>
    </inertial>
  </link>

  <link name="wheel_back_left">
    <visual>
      <geometry>
        <cylinder radius="0.05" length="0.04"/>
      </geometry>
      <material name="black">
        <color rgba="0 0 0 1"/>
      </material>
    </visual>
    <collision>
      <geometry>
        <cylinder radius="0.05" length="0.04"/>
      </geometry>
    </collision>
    <inertial>
      <mass value="0.1"/>
      <inertia ixx="0.001" ixy="0" ixz="0" iyy="0.001" iyz="0" izz="0.001"/>
    </inertial>
  </link>

  <link name="wheel_back_right">
    <visual>
      <geometry>
        <cylinder radius="0.05" length="0.04"/>
      </geometry>
      <material name="black">
        <color rgba="0 0 0 1"/>
      </material>
    </visual>
    <collision>
      <geometry>
        <cylinder radius="0.05" length="0.04"/>
      </geometry>
    </collision>
    <inertial>
      <mass value="0.1"/>
      <inertia ixx="0.001" ixy="0" ixz="0" iyy="0.001" iyz="0" izz="0.001"/>
    </inertial>
  </link>

  <!-- Joints -->
  <joint name="wheel_front_left_joint" type="continuous">
    <parent link="base_link"/>
    <child link="wheel_front_left"/>
    <origin xyz="0.2 0.17 0" rpy="1.5708 0 0"/>
    <axis xyz="0 0 1"/>
  </joint>

  <joint name="wheel_front_right_joint" type="continuous">
    <parent link="base_link"/>
    <child link="wheel_front_right"/>
    <origin xyz="0.2 -0.17 0" rpy="1.5708 0 0"/>
    <axis xyz="0 0 -1"/>
  </joint>

  <joint name="wheel_back_left_joint" type="continuous">
    <parent link="base_link"/>
    <child link="wheel_back_left"/>
    <origin xyz="-0.2 0.17 0" rpy="1.5708 0 0"/>
    <axis xyz="0 0 1"/>
  </joint>

  <joint name="wheel_back_right_joint" type="continuous">
    <parent link="base_link"/>
    <child link="wheel_back_right"/>
    <origin xyz="-0.2 -0.17 0" rpy="1.5708 0 0"/>
    <axis xyz="0 0 -1"/>
  </joint>

  <!-- Gazebo plugins -->
  <gazebo>
    <plugin name="differential_drive_controller" filename="libgazebo_ros_diff_drive.so">
      <update_rate>100</update_rate>
      <left_joint>wheel_front_left_joint wheel_back_left_joint</left_joint>
      <right_joint>wheel_front_right_joint wheel_back_right_joint</right_joint>
      <wheel_separation>0.34</wheel_separation>
      <wheel_diameter>0.1</wheel_diameter>
      <max_wheel_torque>20</max_wheel_torque>
      <max_wheel_acceleration>1.0</max_wheel_acceleration>
      <command_topic>cmd_vel</command_topic>
      <odometry_topic>odom</odometry_topic>
      <odometry_frame>odom</odometry_frame>
      <robot_base_frame>base_link</robot_base_frame>
    </plugin>
  </gazebo>

  <!-- IMU plugin -->
  <gazebo>
    <plugin name="imu_plugin" filename="libgazebo_ros_imu_sensor.so">
      <topicName>imu</topicName>
      <bodyName>base_link</bodyName>
      <updateRateHZ>100.0</updateRateHZ>
      <gaussianNoise>0.0</gaussianNoise>
      <xyzOffset>0 0 0</xyzOffset>
      <rpyOffset>0 0 0</rpyOffset>
      <frameName>base_link</frameName>
    </plugin>
  </gazebo>

  <!-- RealSense D435 plugin -->
  <gazebo>
    <plugin name="realsense_plugin" filename="libgazebo_ros_camera.so">
      <camera_name>camera</camera_name>
      <image_topic_name>camera/image_raw</image_topic_name>
      <camera_info_topic_name>camera/camera_info</camera_info_topic_name>
      <frame_name>camera_link</frame_name>
      <baseline>0.07</baseline>
      <updateRate>30.0</updateRate>
      <width>640</width>
      <height>480</height>
      <format>R8G8B8</format>
      <clip>0.1</clip>
      <noise>0.0</noise>
    </plugin>
  </gazebo>

</robot> 